2025-01-02 01:06:59,060 - root - INFO - Starting the training pipeline.
2025-01-02 01:06:59,060 - root - INFO - Enter the data ingestion method or component!
2025-01-02 01:06:59,060 - root - INFO - Read the dataset as dataframe!
2025-01-02 01:06:59,060 - root - INFO - Train Test Split Initiated!
2025-01-02 01:06:59,074 - root - INFO - Ingestion of data is completed!
2025-01-02 01:06:59,074 - root - INFO - Data ingestion completed. Train data path: artifacts\train.csv, Test data path: artifacts\test.csv
2025-01-02 01:06:59,090 - root - INFO - Read train and test data completed
2025-01-02 01:06:59,090 - root - INFO - Obtaining preprocessing object
2025-01-02 01:06:59,090 - root - INFO - Categorical columns: ['gender', 'race_ethnicity', 'parental_level_of_education', 'lunch', 'test_preparation_course']
2025-01-02 01:06:59,090 - root - INFO - Numerical columns: ['writing_score', 'reading_score']
2025-01-02 01:06:59,090 - root - INFO - Applying preprocessing object on training dataframe and testing dataframe.
2025-01-02 01:06:59,106 - root - INFO - Saved preprocessing object.
2025-01-02 01:06:59,106 - root - INFO - Data transformation completed.
2025-01-02 01:07:01,145 - root - INFO - Split training and test input data
2025-01-02 01:07:01,709 - root - ERROR - Error occurred in the training pipeline.
Traceback (most recent call last):
  File "e:\praxis-learning\mlproject\src\utils.py", line 33, in evaluate_models
    gs.fit(X_train,y_train)
  File "C:\Users\prakhar\anaconda\envs\mlops\lib\site-packages\sklearn\base.py", line 1389, in wrapper
    return fit_method(estimator, *args, **kwargs)
  File "C:\Users\prakhar\anaconda\envs\mlops\lib\site-packages\sklearn\model_selection\_search.py", line 1023, in fit
    self._run_search(evaluate_candidates)
  File "C:\Users\prakhar\anaconda\envs\mlops\lib\site-packages\sklearn\model_selection\_search.py", line 1570, in _run_search
    evaluate_candidates(ParameterGrid(self.param_grid))
  File "C:\Users\prakhar\anaconda\envs\mlops\lib\site-packages\sklearn\model_selection\_search.py", line 969, in evaluate_candidates
    out = parallel(
  File "C:\Users\prakhar\anaconda\envs\mlops\lib\site-packages\sklearn\utils\parallel.py", line 77, in __call__
    return super().__call__(iterable_with_config)
  File "C:\Users\prakhar\anaconda\envs\mlops\lib\site-packages\joblib\parallel.py", line 2007, in __call__
    return output if self.return_generator else list(output)
  File "C:\Users\prakhar\anaconda\envs\mlops\lib\site-packages\joblib\parallel.py", line 1650, in _get_outputs
    yield from self._retrieve()
  File "C:\Users\prakhar\anaconda\envs\mlops\lib\site-packages\joblib\parallel.py", line 1754, in _retrieve
    self._raise_error_fast()
  File "C:\Users\prakhar\anaconda\envs\mlops\lib\site-packages\joblib\parallel.py", line 1789, in _raise_error_fast
    error_job.get_result(self.timeout)
  File "C:\Users\prakhar\anaconda\envs\mlops\lib\site-packages\joblib\parallel.py", line 745, in get_result
    return self._return_or_raise()
  File "C:\Users\prakhar\anaconda\envs\mlops\lib\site-packages\joblib\parallel.py", line 763, in _return_or_raise
    raise self._result
joblib.externals.loky.process_executor.TerminatedWorkerError: A worker process managed by the executor was unexpectedly terminated. This could be caused by a segmentation fault while calling the function or by an excessive memory usage causing the Operating System to kill the worker.


During handling of the above exception, another exception occurred:

Traceback (most recent call last):
  File "e:\praxis-learning\mlproject\src\components\model_trainer.py", line 71, in initiate_model_trainer
    model_report: dict = evaluate_models(
  File "e:\praxis-learning\mlproject\src\utils.py", line 49, in evaluate_models
    raise CustomException(e,sys)
src.exception.CustomException: Error occurred in python script name [e:\praxis-learning\mlproject\src\utils.py] line number [33] error message [A worker process managed by the executor was unexpectedly terminated. This could be caused by a segmentation fault while calling the function or by an excessive memory usage causing the Operating System to kill the worker.
]

During handling of the above exception, another exception occurred:

Traceback (most recent call last):
  File "E:\Praxis-Learning\mlproject\src\pipeline\train_pipeline.py", line 22, in train_pipeline
    best_model_name, r2_square = model_trainer.initiate_model_trainer(train_array, test_array)
  File "e:\praxis-learning\mlproject\src\components\model_trainer.py", line 138, in initiate_model_trainer
    raise CustomException(e, sys)
src.exception.CustomException: Error occurred in python script name [e:\praxis-learning\mlproject\src\components\model_trainer.py] line number [71] error message [Error occurred in python script name [e:\praxis-learning\mlproject\src\utils.py] line number [33] error message [A worker process managed by the executor was unexpectedly terminated. This could be caused by a segmentation fault while calling the function or by an excessive memory usage causing the Operating System to kill the worker.
]]
