2025-01-02 00:56:23,716 - root - INFO - Starting the training pipeline.
2025-01-02 00:56:23,716 - root - INFO - Enter the data ingestion method or component!
2025-01-02 00:56:23,732 - root - INFO - Read the dataset as dataframe!
2025-01-02 00:56:23,732 - root - INFO - Train Test Split Initiated!
2025-01-02 00:56:23,732 - root - INFO - Ingestion of data is completed!
2025-01-02 00:56:23,732 - root - INFO - Data ingestion completed. Train data path: artifacts\train.csv, Test data path: artifacts\test.csv
2025-01-02 00:56:23,747 - root - INFO - Read train and test data completed
2025-01-02 00:56:23,747 - root - INFO - Obtaining preprocessing object
2025-01-02 00:56:23,747 - root - INFO - Categorical columns: ['gender', 'race_ethnicity', 'parental_level_of_education', 'lunch', 'test_preparation_course']
2025-01-02 00:56:23,747 - root - INFO - Numerical columns: ['writing_score', 'reading_score']
2025-01-02 00:56:23,747 - root - INFO - Applying preprocessing object on training dataframe and testing dataframe.
2025-01-02 00:56:23,763 - root - INFO - Saved preprocessing object.
2025-01-02 00:56:23,779 - root - INFO - Data transformation completed.
2025-01-02 00:56:25,848 - root - INFO - Split training and test input data
2025-01-02 00:56:54,860 - root - INFO - Best found model on both training and testing dataset
2025-01-02 00:56:59,476 - root - ERROR - Error occurred in the training pipeline.
Traceback (most recent call last):
  File "e:\praxis-learning\mlproject\src\components\model_trainer.py", line 140, in initiate_model_trainer
    raise CustomException("No active MLflow run found for model registration.")
TypeError: __init__() missing 1 required positional argument: 'error_detail'

During handling of the above exception, another exception occurred:

Traceback (most recent call last):
  File "E:\Praxis-Learning\mlproject\src\pipeline\train_pipeline.py", line 22, in train_pipeline
    best_model_name, r2_square = model_trainer.initiate_model_trainer(train_array, test_array)
  File "e:\praxis-learning\mlproject\src\components\model_trainer.py", line 153, in initiate_model_trainer
    raise CustomException(e, sys)
src.exception.CustomException: Error occurred in python script name [e:\praxis-learning\mlproject\src\components\model_trainer.py] line number [140] error message [__init__() missing 1 required positional argument: 'error_detail']
